Traceback (most recent call last):
  File "sacwo_20210404.py", line 290, in <module>
    critic_1_loss, critic_2_loss, policy_loss, ent_loss, alpha = agent.update_parameters(memory, args.batch_size, updates)
  File "/home/elp21aau/SACCT/SACCT/Benchmarks/sacwo/sac.py", line 84, in update_parameters
    qf1, qf2 = self.critic(state_batch, action_batch)  # Two Q-functions to mitigate positive bias in the policy improvement step
  File "/home/elp21aau/.conda/envs/pytorch/lib/python3.6/site-packages/torch/nn/modules/module.py", line 889, in _call_impl
    result = self.forward(*input, **kwargs)
  File "/home/elp21aau/SACCT/SACCT/Benchmarks/sacwo/model.py", line 53, in forward
    x1 = F.relu(self.linear1(xu))
  File "/home/elp21aau/.conda/envs/pytorch/lib/python3.6/site-packages/torch/nn/modules/module.py", line 889, in _call_impl
    result = self.forward(*input, **kwargs)
  File "/home/elp21aau/.conda/envs/pytorch/lib/python3.6/site-packages/torch/nn/modules/linear.py", line 94, in forward
    return F.linear(input, self.weight, self.bias)
  File "/home/elp21aau/.conda/envs/pytorch/lib/python3.6/site-packages/torch/nn/functional.py", line 1753, in linear
    return torch._C._nn.linear(input, weight, bias)
RuntimeError: mat1 and mat2 shapes cannot be multiplied (256x23 and 24x256)
python3: can't open file 'sacwo.py': [Errno 2] No such file or directory
Traceback (most recent call last):
  File "sacwo_20210404.py", line 230, in <module>
    agent = SAC(N_S,action_space , args)
  File "/home/elp21aau/SACCT/SACCT/Benchmarks/sacwo/sac.py", line 25, in __init__
    self.critic = QNetwork(num_inputs, action_space.shape[0], args.hidden_size).to(device=self.device)
  File "/home/elp21aau/.conda/envs/pytorch/lib/python3.6/site-packages/torch/nn/modules/module.py", line 673, in to
    return self._apply(convert)
  File "/home/elp21aau/.conda/envs/pytorch/lib/python3.6/site-packages/torch/nn/modules/module.py", line 387, in _apply
    module._apply(fn)
  File "/home/elp21aau/.conda/envs/pytorch/lib/python3.6/site-packages/torch/nn/modules/module.py", line 409, in _apply
    param_applied = fn(param)
  File "/home/elp21aau/.conda/envs/pytorch/lib/python3.6/site-packages/torch/nn/modules/module.py", line 671, in convert
    return t.to(device, dtype if t.is_floating_point() or t.is_complex() else None, non_blocking)
  File "/home/elp21aau/.conda/envs/pytorch/lib/python3.6/site-packages/torch/cuda/__init__.py", line 170, in _lazy_init
    torch._C._cuda_init()
RuntimeError: Found no NVIDIA driver on your system. Please check that you have an NVIDIA GPU and installed a driver from http://www.nvidia.com/Download/index.aspx
